Workbook

Sheet Dashboard
B1: PLACEMENT INSIGHTS 360 | Campus Placement Analytics
B4: Select Batch > | C4: All | E4: Synthetic data | all numbers are live formulas | change the batch to refresh every card and chart
B6: TOTAL STUDENTS | D6: PLACED | F6: PLACEMENT RATE | H6: AVG CTC | J6: HIGHEST CTC | L6: ACTIVE RECRUITERS
B7: =Analysis!B5 -> 600 | D7: =Analysis!B6 -> 388 | F7: =Analysis!B7 -> 0.64666667 | H7: =Analysis!B8 -> 10.240979 | J7: =Analysis!B10 -> 29.9 | L7: =Analysis!B14 -> 30
B10: ="> Best course by placement rate: "&INDEX(Analysis!A20:A24,MATCH(MAX(Analysis!D20:D24),Analysis!D20:D24,0))&" ("&TEXT(MAX(Analysis!D20:D24),"0.0%")&")" -> > Best course by placement rate: DSA with Java (76.5%)
B11: ="> Top recruiter: "&Analysis!B83&" with "&Analysis!E83&" hires at an average of "&TEXT(Analysis!F83,"0.0")&" LPA" -> > Top recruiter: Sapphire Infotech with 20 hires at an average of 5.8 LPA
B12: ="> Elite-tier students are placed at "&TEXT(Analysis!D47,"0%")&" vs "&TEXT(Analysis!D44,"0%")&" for Foundation-tier students" -> > Elite-tier students are placed at 93% vs 29% for Foundation-tier students

Sheet About
A1: Placement Insights 360
A2: Purpose | B2: End-to-end analytics of a campus placement cycle: readiness, hiring funnel, packages and recruiters.
A3: Data | B3: 100% synthetic (600 students, 30 fictional companies, ~3,100 applications). Generated by scripts/generate_data.py.
A5: SHEET GUIDE
A6: Dashboard | B6: Batch dropdown (C4), KPI cards, auto-insight sentences and 6 charts - all driven by formulas.
A7: Analysis | B7: The calculation engine: 9 summary tables that feed the dashboard.
A8: Students | B8: Raw student attributes + calculated Readiness Score / Tier, Offers, Placed, CTC, Company.
A9: Applications | B9: One row per application. Lookup columns pull Batch, Course, Sector, Tier from other sheets.
A10: Companies | B10: Recruiter master + live Applications / Offers / Hires / Avg CTC (respond to the batch selector).
A11: Assumptions | B11: Editable weights, tier thresholds, CTC bands, stage order. Blue font = input.
A13: EXCEL TECHNIQUES USED
A14: Lookups | B14: INDEX/MATCH two-way lookups across sheets; approximate-match LOOKUP for tier banding.
A15: Conditional aggregation | B15: COUNTIFS / SUMIFS / AVERAGEIFS / MAXIFS with a wildcard criterion so one dropdown means 'All' or one batch.
A16: Array formula | B16: Median CTC with MEDIAN(IF(...)) entered as a CSE array formula.
A17: Top-N ranking | B17: LARGE + MATCH with a ROW()-based tie-breaker column (Companies!K) - no sorting needed.
A18: Data model hygiene | B18: Excel Tables (tblStudents, tblApplications, tblCompanies), data validation, frozen panes, named assumptions.
A19: Visual analytics | B19: Data bars, colour scales, icon sets, rule-based formatting, 6 native charts.
A20: Dynamic text | B20: Insight sentences built with INDEX/MATCH + TEXT that rewrite themselves per batch.
A22: NOTE | B22: Independent portfolio project. Not affiliated with or endorsed by any training company.

Sheet Analysis
A1: Analysis Engine (feeds the Dashboard)
A2: Batch criterion (from Dashboard) | B2: =IF(Dashboard!$C$4="All","*",Dashboard!$C$4) -> * | C2: ="Showing: "&Dashboard!$C$4 -> Showing: All
A4: 1. Headline KPIs
A5: Total Students | B5: =COUNTIFS(Students!$C$2:$C$601,$B$2) -> 600
A6: Placed Students | B6: =COUNTIFS(Students!$C$2:$C$601,$B$2,Students!$O$2:$O$601,"Yes") -> 388
A7: Placement Rate | B7: =IF(B5=0,0,B6/B5) -> 0.64666667
A8: Average CTC (LPA) | B8: =IFERROR(AVERAGEIFS(Students!$P$2:$P$601,Students!$C$2:$C$601,$B$2,Students!$O$2:$O$601,"Yes"),0) -> 10.240979
A9: Median CTC (LPA) | B9: {=IFERROR(MEDIAN(IF((Students!$O$2:$O$601="Yes")*((($B$2="*")+(Students!$C$2:$C$601=$B$2))>0),Students!$P$2:$P$601)),0)} -> 8.35
A10: Highest CTC (LPA) | B10: =_xlfn.MAXIFS(Students!$P$2:$P$601,Students!$C$2:$C$601,$B$2,Students!$O$2:$O$601,"Yes") -> 29.9
A11: Total Applications | B11: =COUNTIFS(Applications!$J$2:$J$3144,$B$2) -> 3143
A12: Offers Made | B12: =COUNTIFS(Applications!$J$2:$J$3144,$B$2,Applications!$F$2:$F$3144,"Offered") -> 876
A13: Offer-to-Hire Conversion | B13: =IF(B12=0,0,B6/B12) -> 0.44292237
A14: Active Recruiters (>=1 hire) | B14: =COUNTIF(Companies!$H$2:$H$31,">0") -> 30
A15: Avg Applications / Student | B15: =IF(B5=0,0,B11/B5) -> 5.2383333
A18: 2. Placement by Course
A19: Course | B19: Students | C19: Placed | D19: Placement Rate | E19: Avg CTC (LPA)
A20: Cybersecurity | B20: =COUNTIFS(Students!$D$2:$D$601,$A20,Students!$C$2:$C$601,$B$2) -> 61 | C20: =COUNTIFS(Students!$D$2:$D$601,$A20,Students!$C$2:$C$601,$B$2,Students!$O$2:$O$601,"Yes") -> 39 | D20: =IF(B20=0,0,C20/B20) -> 0.63934426 | E20: =IFERROR(AVERAGEIFS(Students!$P$2:$P$601,Students!$D$2:$D$601,$A20,Students!$C$2:$C$601,$B$2,Students!$O$2:$O$601,"Yes"),0) -> 8.4641026
A21: DSA with Java | B21: =COUNTIFS(Students!$D$2:$D$601,$A21,Students!$C$2:$C$601,$B$2) -> 162 | C21: =COUNTIFS(Students!$D$2:$D$601,$A21,Students!$C$2:$C$601,$B$2,Students!$O$2:$O$601,"Yes") -> 124 | D21: =IF(B21=0,0,C21/B21) -> 0.7654321 | E21: =IFERROR(AVERAGEIFS(Students!$P$2:$P$601,Students!$D$2:$D$601,$A21,Students!$C$2:$C$601,$B$2,Students!$O$2:$O$601,"Yes"),0) -> 11.985484
A22: Data Analytics | B22: =COUNTIFS(Students!$D$2:$D$601,$A22,Students!$C$2:$C$601,$B$2) -> 100 | C22: =COUNTIFS(Students!$D$2:$D$601,$A22,Students!$C$2:$C$601,$B$2,Students!$O$2:$O$601,"Yes") -> 51 | D22: =IF(B22=0,0,C22/B22) -> 0.51 | E22: =IFERROR(AVERAGEIFS(Students!$P$2:$P$601,Students!$D$2:$D$601,$A22,Students!$C$2:$C$601,$B$2,Students!$O$2:$O$601,"Yes"),0) -> 9.9254902
A23: Data Science & ML | B23: =COUNTIFS(Students!$D$2:$D$601,$A23,Students!$C$2:$C$601,$B$2) -> 110 | C23: =COUNTIFS(Students!$D$2:$D$601,$A23,Students!$C$2:$C$601,$B$2,Students!$O$2:$O$601,"Yes") -> 73 | D23: =IF(B23=0,0,C23/B23) -> 0.66363636 | E23: =IFERROR(AVERAGEIFS(Students!$P$2:$P$601,Students!$D$2:$D$601,$A23,Students!$C$2:$C$601,$B$2,Students!$O$2:$O$601,"Yes"),0) -> 10.167123
A24: Full Stack Development | B24: =COUNTIFS(Students!$D$2:$D$601,$A24,Students!$C$2:$C$601,$B$2) -> 167 | C24: =COUNTIFS(Students!$D$2:$D$601,$A24,Students!$C$2:$C$601,$B$2,Students!$O$2:$O$601,"Yes") -> 101 | D24: =IF(B24=0,0,C24/B24) -> 0.60479042 | E24: =IFERROR(AVERAGEIFS(Students!$P$2:$P$601,Students!$D$2:$D$601,$A24,Students!$C$2:$C$601,$B$2,Students!$O$2:$O$601,"Yes"),0) -> 8.9980198
A26: 3. Hiring Funnel (applications reaching each stage)
A27: Stage | B27: Applications | C27: % of Applied
A28: =Assumptions!K4 -> Applied | B28: =COUNTIFS(Applications!$J$2:$J$3144,$B$2,Applications!$N$2:$N$3144,">="&MATCH(A28,Assumptions!$K$4:$K$8,0)) -> 3143 | C28: =IF($B$28=0,0,B28/$B$28) -> 1
A29: =Assumptions!K5 -> Online Test | B29: =COUNTIFS(Applications!$J$2:$J$3144,$B$2,Applications!$N$2:$N$3144,">="&MATCH(A29,Assumptions!$K$4:$K$8,0)) -> 2149 | C29: =IF($B$28=0,0,B29/$B$28) -> 0.68374165
A30: =Assumptions!K6 -> Technical Interview | B30: =COUNTIFS(Applications!$J$2:$J$3144,$B$2,Applications!$N$2:$N$3144,">="&MATCH(A30,Assumptions!$K$4:$K$8,0)) -> 1525 | C30: =IF($B$28=0,0,B30/$B$28) -> 0.48520522
A31: =Assumptions!K7 -> HR Interview | B31: =COUNTIFS(Applications!$J$2:$J$3144,$B$2,Applications!$N$2:$N$3144,">="&MATCH(A31,Assumptions!$K$4:$K$8,0)) -> 1124 | C31: =IF($B$28=0,0,B31/$B$28) -> 0.35762011
A32: =Assumptions!K8 -> Offered | B32: =COUNTIFS(Applications!$J$2:$J$3144,$B$2,Applications!$N$2:$N$3144,">="&MATCH(A32,Assumptions!$K$4:$K$8,0)) -> 876 | C32: =IF($B$28=0,0,B32/$B$28) -> 0.2787146
A34: 4. Placed Students by CTC Band
A35: CTC Band | B35: Students | C35: % of Placed
A36: =Assumptions!G4 -> Below 5 LPA | B36: =COUNTIFS(Students!$P$2:$P$601,">="&Assumptions!H4,Students!$P$2:$P$601,"<"&Assumptions!I4,Students!$O$2:$O$601,"Yes",Students!$C$2:$C$601,$B$2) -> 26 | C36: =IF($B$6=0,0,B36/$B$6) -> 0.067010309
A37: =Assumptions!G5 -> 5 - 8 LPA | B37: =COUNTIFS(Students!$P$2:$P$601,">="&Assumptions!H5,Students!$P$2:$P$601,"<"&Assumptions!I5,Students!$O$2:$O$601,"Yes",Students!$C$2:$C$601,$B$2) -> 164 | C37: =IF($B$6=0,0,B37/$B$6) -> 0.42268041
A38: =Assumptions!G6 -> 8 - 12 LPA | B38: =COUNTIFS(Students!$P$2:$P$601,">="&Assumptions!H6,Students!$P$2:$P$601,"<"&Assumptions!I6,Students!$O$2:$O$601,"Yes",Students!$C$2:$C$601,$B$2) -> 73 | C38: =IF($B$6=0,0,B38/$B$6) -> 0.18814433
A39: =Assumptions!G7 -> 12 - 18 LPA | B39: =COUNTIFS(Students!$P$2:$P$601,">="&Assumptions!H7,Students!$P$2:$P$601,"<"&Assumptions!I7,Students!$O$2:$O$601,"Yes",Students!$C$2:$C$601,$B$2) -> 89 | C39: =IF($B$6=0,0,B39/$B$6) -> 0.22938144
A40: =Assumptions!G8 -> 18+ LPA | B40: =COUNTIFS(Students!$P$2:$P$601,">="&Assumptions!H8,Students!$P$2:$P$601,"<"&Assumptions!I8,Students!$O$2:$O$601,"Yes",Students!$C$2:$C$601,$B$2) -> 36 | C40: =IF($B$6=0,0,B40/$B$6) -> 0.092783505
A42: 5. Readiness Tier vs Outcome
A43: Readiness Tier | B43: Students | C43: Placed | D43: Placement Rate | E43: Avg CTC (LPA)
A44: =Assumptions!E4 -> Foundation | B44: =COUNTIFS(Students!$L$2:$L$601,$A44,Students!$C$2:$C$601,$B$2) -> 116 | C44: =COUNTIFS(Students!$L$2:$L$601,$A44,Students!$C$2:$C$601,$B$2,Students!$O$2:$O$601,"Yes") -> 34 | D44: =IF(B44=0,0,C44/B44) -> 0.29310345 | E44: =IFERROR(AVERAGEIFS(Students!$P$2:$P$601,Students!$L$2:$L$601,$A44,Students!$C$2:$C$601,$B$2,Students!$O$2:$O$601,"Yes"),0) -> 6.1617647
A45: =Assumptions!E5 -> Developing | B45: =COUNTIFS(Students!$L$2:$L$601,$A45,Students!$C$2:$C$601,$B$2) -> 261 | C45: =COUNTIFS(Students!$L$2:$L$601,$A45,Students!$C$2:$C$601,$B$2,Students!$O$2:$O$601,"Yes") -> 165 | D45: =IF(B45=0,0,C45/B45) -> 0.63218391 | E45: =IFERROR(AVERAGEIFS(Students!$P$2:$P$601,Students!$L$2:$L$601,$A45,Students!$C$2:$C$601,$B$2,Students!$O$2:$O$601,"Yes"),0) -> 8.5121212
A46: =Assumptions!E6 -> Job-Ready | B46: =COUNTIFS(Students!$L$2:$L$601,$A46,Students!$C$2:$C$601,$B$2) -> 193 | C46: =COUNTIFS(Students!$L$2:$L$601,$A46,Students!$C$2:$C$601,$B$2,Students!$O$2:$O$601,"Yes") -> 161 | D46: =IF(B46=0,0,C46/B46) -> 0.83419689 | E46: =IFERROR(AVERAGEIFS(Students!$P$2:$P$601,Students!$L$2:$L$601,$A46,Students!$C$2:$C$601,$B$2,Students!$O$2:$O$601,"Yes"),0) -> 11.554658
...

Sheet Students
A1: Student ID | B1: Student Name | C1: Batch | D1: Course | E1: City Tier | F1: CGPA | G1: DSA Problems Solved | H1: Projects | I1: Internship | J1: Mock Interview Score | K1: Readiness Score | L1: Readiness Tier | M1: Applications | N1: Offers | O1: Placed | P1: Placed CTC (LPA) | Q1: Placed Company
A2: S0001 | B2: Nikhil Das | C2: Batch 2024 | D2: DSA with Java | E2: Tier 3 | F2: 8.35 | G2: 509 | H2: 2 | I2: No | J2: 62 | K2: =ROUND(Assumptions!$B$4*MIN(G2/Assumptions!$B$11,1)*100+Assumptions!$B$5*F2/10*100+Assumptions!$B$6*MIN(H2/Assumptions!$B$12,1)*100+Assumptions!$B$7*J2+Assumptions!$B$8*IF(I2="Yes",100,0),1) -> 67.1 | L2: =LOOKUP(K2,Assumptions!$D$4:$D$7,Assumptions!$E$4:$E$7) -> Job-Ready | M2: =COUNTIFS(Applications!$B$2:$B$3144,A2) -> 7 | N2: =COUNTIFS(Applications!$B$2:$B$3144,A2,Applications!$F$2:$F$3144,"Offered") -> 3 | O2: =IF(COUNTIFS(Applications!$B$2:$B$3144,A2,Applications!$H$2:$H$3144,"Yes")>0,"Yes","No") -> Yes | P2: =SUMIFS(Applications!$G$2:$G$3144,Applications!$B$2:$B$3144,A2,Applications!$H$2:$H$3144,"Yes") -> 23.9 | Q2: =IF(O2="Yes",INDEX(Companies!$B$2:$B$31,MATCH(INDEX(Applications!$C$2:$C$3144,MATCH(A2,Applications!$P$2:$P$3144,0)),Companies!$A$2:$A$31,0)),"-") -> HelixSecure
A3: S0002 | B3: Rahul Banerjee | C3: Batch 2024 | D3: DSA with Java | E3: Tier 1 | F3: 7.83 | G3: 275 | H3: 6 | I3: No | J3: 67 | K3: =ROUND(Assumptions!$B$4*MIN(G3/Assumptions!$B$11,1)*100+Assumptions!$B$5*F3/10*100+Assumptions!$B$6*MIN(H3/Assumptions!$B$12,1)*100+Assumptions!$B$7*J3+Assumptions!$B$8*IF(I3="Yes",100,0),1) -> 65.6 | L3: =LOOKUP(K3,Assumptions!$D$4:$D$7,Assumptions!$E$4:$E$7) -> Job-Ready | M3: =COUNTIFS(Applications!$B$2:$B$3144,A3) -> 3 | N3: =COUNTIFS(Applications!$B$2:$B$3144,A3,Applications!$F$2:$F$3144,"Offered") -> 1 | O3: =IF(COUNTIFS(Applications!$B$2:$B$3144,A3,Applications!$H$2:$H$3144,"Yes")>0,"Yes","No") -> Yes | P3: =SUMIFS(Applications!$G$2:$G$3144,Applications!$B$2:$B$3144,A3,Applications!$H$2:$H$3144,"Yes") -> 9.6 | Q3: =IF(O3="Yes",INDEX(Companies!$B$2:$B$31,MATCH(INDEX(Applications!$C$2:$C$3144,MATCH(A3,Applications!$P$2:$P$3144,0)),Companies!$A$2:$A$31,0)),"-") -> LearnLoop
A4: S0003 | B4: Ayush Pandey | C4: Batch 2024 | D4: Full Stack Development | E4: Tier 3 | F4: 7.13 | G4: 193 | H4: 2 | I4: No | J4: 50 | K4: =ROUND(Assumptions!$B$4*MIN(G4/Assumptions!$B$11,1)*100+Assumptions!$B$5*F4/10*100+Assumptions!$B$6*MIN(H4/Assumptions!$B$12,1)*100+Assumptions!$B$7*J4+Assumptions!$B$8*IF(I4="Yes",100,0),1) -> 43.8 | L4: =LOOKUP(K4,Assumptions!$D$4:$D$7,Assumptions!$E$4:$E$7) -> Foundation | M4: =COUNTIFS(Applications!$B$2:$B$3144,A4) -> 1 | N4: =COUNTIFS(Applications!$B$2:$B$3144,A4,Applications!$F$2:$F$3144,"Offered") -> 0 | O4: =IF(COUNTIFS(Applications!$B$2:$B$3144,A4,Applications!$H$2:$H$3144,"Yes")>0,"Yes","No") -> No | P4: =SUMIFS(Applications!$G$2:$G$3144,Applications!$B$2:$B$3144,A4,Applications!$H$2:$H$3144,"Yes") -> 0 | Q4: =IF(O4="Yes",INDEX(Companies!$B$2:$B$31,MATCH(INDEX(Applications!$C$2:$C$3144,MATCH(A4,Applications!$P$2:$P$3144,0)),Companies!$A$2:$A$31,0)),"-") -> -
A5: S0004 | B5: Aman Das | C5: Batch 2024 | D5: DSA with Java | E5: Tier 3 | F5: 6.45 | G5: 625 | H5: 4 | I5: Yes | J5: 62 | K5: =ROUND(Assumptions!$B$4*MIN(G5/Assumptions!$B$11,1)*100+Assumptions!$B$5*F5/10*100+Assumptions!$B$6*MIN(H5/Assumptions!$B$12,1)*100+Assumptions!$B$7*J5+Assumptions!$B$8*IF(I5="Yes",100,0),1) -> 81.3 | L5: =LOOKUP(K5,Assumptions!$D$4:$D$7,Assumptions!$E$4:$E$7) -> Elite | M5: =COUNTIFS(Applications!$B$2:$B$3144,A5) -> 5 | N5: =COUNTIFS(Applications!$B$2:$B$3144,A5,Applications!$F$2:$F$3144,"Offered") -> 1 | O5: =IF(COUNTIFS(Applications!$B$2:$B$3144,A5,Applications!$H$2:$H$3144,"Yes")>0,"Yes","No") -> Yes | P5: =SUMIFS(Applications!$G$2:$G$3144,Applications!$B$2:$B$3144,A5,Applications!$H$2:$H$3144,"Yes") -> 12.8 | Q5: =IF(O5="Yes",INDEX(Companies!$B$2:$B$31,MATCH(INDEX(Applications!$C$2:$C$3144,MATCH(A5,Applications!$P$2:$P$3144,0)),Companies!$A$2:$A$31,0)),"-") -> PayRiver
A6: S0005 | B6: Tushar Tiwari | C6: Batch 2024 | D6: DSA with Java | E6: Tier 3 | F6: 7.21 | G6: 368 | H6: 1 | I6: No | J6: 75 | K6: =ROUND(Assumptions!$B$4*MIN(G6/Assumptions!$B$11,1)*100+Assumptions!$B$5*F6/10*100+Assumptions!$B$6*MIN(H6/Assumptions!$B$12,1)*100+Assumptions!$B$7*J6+Assumptions!$B$8*IF(I6="Yes",100,0),1) -> 55.5 | L6: =LOOKUP(K6,Assumptions!$D$4:$D$7,Assumptions!$E$4:$E$7) -> Developing | M6: =COUNTIFS(Applications!$B$2:$B$3144,A6) -> 4 | N6: =COUNTIFS(Applications!$B$2:$B$3144,A6,Applications!$F$2:$F$3144,"Offered") -> 1 | O6: =IF(COUNTIFS(Applications!$B$2:$B$3144,A6,Applications!$H$2:$H$3144,"Yes")>0,"Yes","No") -> Yes | P6: =SUMIFS(Applications!$G$2:$G$3144,Applications!$B$2:$B$3144,A6,Applications!$H$2:$H$3144,"Yes") -> 6.1 | Q6: =IF(O6="Yes",INDEX(Companies!$B$2:$B$31,MATCH(INDEX(Applications!$C$2:$C$3144,MATCH(A6,Applications!$P$2:$P$3144,0)),Companies!$A$2:$A$31,0)),"-") -> HealthLink Digital
A7: S0006 | B7: Arjun Jain | C7: Batch 2024 | D7: Data Analytics | E7: Tier 2 | F7: 8.03 | G7: 234 | H7: 0 | I7: No | J7: 74 | K7: =ROUND(Assumptions!$B$4*MIN(G7/Assumptions!$B$11,1)*100+Assumptions!$B$5*F7/10*100+Assumptions!$B$6*MIN(H7/Assumptions!$B$12,1)*100+Assumptions!$B$7*J7+Assumptions!$B$8*IF(I7="Yes",100,0),1) -> 44.9 | L7: =LOOKUP(K7,Assumptions!$D$4:$D$7,Assumptions!$E$4:$E$7) -> Foundation | M7: =COUNTIFS(Applications!$B$2:$B$3144,A7) -> 9 | N7: =COUNTIFS(Applications!$B$2:$B$3144,A7,Applications!$F$2:$F$3144,"Offered") -> 0 | O7: =IF(COUNTIFS(Applications!$B$2:$B$3144,A7,Applications!$H$2:$H$3144,"Yes")>0,"Yes","No") -> No | P7: =SUMIFS(Applications!$G$2:$G$3144,Applications!$B$2:$B$3144,A7,Applications!$H$2:$H$3144,"Yes") -> 0 | Q7: =IF(O7="Yes",INDEX(Companies!$B$2:$B$31,MATCH(INDEX(Applications!$C$2:$C$3144,MATCH(A7,Applications!$P$2:$P$3144,0)),Companies!$A$2:$A$31,0)),"-") -> -
A8: S0007 | B8: Mohit Malhotra | C8: Batch 2024 | D8: Data Science & ML | E8: Tier 1 | F8: 6.67 | G8: 305 | H8: 6 | I8: Yes | J8: 56 | K8: =ROUND(Assumptions!$B$4*MIN(G8/Assumptions!$B$11,1)*100+Assumptions!$B$5*F8/10*100+Assumptions!$B$6*MIN(H8/Assumptions!$B$12,1)*100+Assumptions!$B$7*J8+Assumptions!$B$8*IF(I8="Yes",100,0),1) -> 72.8 | L8: =LOOKUP(K8,Assumptions!$D$4:$D$7,Assumptions!$E$4:$E$7) -> Job-Ready | M8: =COUNTIFS(Applications!$B$2:$B$3144,A8) -> 5 | N8: =COUNTIFS(Applications!$B$2:$B$3144,A8,Applications!$F$2:$F$3144,"Offered") -> 2 | O8: =IF(COUNTIFS(Applications!$B$2:$B$3144,A8,Applications!$H$2:$H$3144,"Yes")>0,"Yes","No") -> Yes | P8: =SUMIFS(Applications!$G$2:$G$3144,Applications!$B$2:$B$3144,A8,Applications!$H$2:$H$3144,"Yes") -> 6.9 | Q8: =IF(O8="Yes",INDEX(Companies!$B$2:$B$31,MATCH(INDEX(Applications!$C$2:$C$3144,MATCH(A8,Applications!$P$2:$P$3144,0)),Companies!$A$2:$A$31,0)),"-") -> RetailRocket
A9: S0008 | B9: Yash Banerjee | C9: Batch 2024 | D9: DSA with Java | E9: Tier 1 | F9: 7.51 | G9: 606 | H9: 3 | I9: No | J9: 41 | K9: =ROUND(Assumptions!$B$4*MIN(G9/Assumptions!$B$11,1)*100+Assumptions!$B$5*F9/10*100+Assumptions!$B$6*MIN(H9/Assumptions!$B$12,1)*100+Assumptions!$B$7*J9+Assumptions!$B$8*IF(I9="Yes",100,0),1) -> 65.2 | L9: =LOOKUP(K9,Assumptions!$D$4:$D$7,Assumptions!$E$4:$E$7) -> Job-Ready | M9: =COUNTIFS(Applications!$B$2:$B$3144,A9) -> 3 | N9: =COUNTIFS(Applications!$B$2:$B$3144,A9,Applications!$F$2:$F$3144,"Offered") -> 2 | O9: =IF(COUNTIFS(Applications!$B$2:$B$3144,A9,Applications!$H$2:$H$3144,"Yes")>0,"Yes","No") -> Yes | P9: =SUMIFS(Applications!$G$2:$G$3144,Applications!$B$2:$B$3144,A9,Applications!$H$2:$H$3144,"Yes") -> 12.3 | Q9: =IF(O9="Yes",INDEX(Companies!$B$2:$B$31,MATCH(INDEX(Applications!$C$2:$C$3144,MATCH(A9,Applications!$P$2:$P$3144,0)),Companies!$A$2:$A$31,0)),"-") -> CloudKraft
A10: S0009 | B10: Meera Menon | C10: Batch 2024 | D10: Full Stack Development | E10: Tier 3 | F10: 6.69 | G10: 209 | H10: 4 | I10: No | J10: 73 | K10: =ROUND(Assumptions!$B$4*MIN(G10/Assumptions!$B$11,1)*100+Assumptions!$B$5*F10/10*100+Assumptions!$B$6*MIN(H10/Assumptions!$B$12,1)*100+Assumptions!$B$7*J10+Assumptions!$B$8*IF(I10="Yes",100,0),1) -> 56.5 | L10: =LOOKUP(K10,Assumptions!$D$4:$D$7,Assumptions!$E$4:$E$7) -> Developing | M10: =COUNTIFS(Applications!$B$2:$B$3144,A10) -> 5 | N10: =COUNTIFS(Applications!$B$2:$B$3144,A10,Applications!$F$2:$F$3144,"Offered") -> 2 | O10: =IF(COUNTIFS(Applications!$B$2:$B$3144,A10,Applications!$H$2:$H$3144,"Yes")>0,"Yes","No") -> Yes | P10: =SUMIFS(Applications!$G$2:$G$3144,Applications!$B$2:$B$3144,A10,Applications!$H$2:$H$3144,"Yes") -> 11 | Q10: =IF(O10="Yes",INDEX(Companies!$B$2:$B$31,MATCH(INDEX(Applications!$C$2:$C$3144,MATCH(A10,Applications!$P$2:$P$3144,0)),Companies!$A$2:$A$31,0)),"-") -> SkillForge
A11: S0010 | B11: Dev Iyer | C11: Batch 2024 | D11: Full Stack Development | E11: Tier 2 | F11: 6.97 | G11: 107 | H11: 5 | I11: No | J11: 65 | K11: =ROUND(Assumptions!$B$4*MIN(G11/Assumptions!$B$11,1)*100+Assumptions!$B$5*F11/10*100+Assumptions!$B$6*MIN(H11/Assumptions!$B$12,1)*100+Assumptions!$B$7*J11+Assumptions!$B$8*IF(I11="Yes",100,0),1) -> 53.4 | L11: =LOOKUP(K11,Assumptions!$D$4:$D$7,Assumptions!$E$4:$E$7) -> Developing | M11: =COUNTIFS(Applications!$B$2:$B$3144,A11) -> 5 | N11: =COUNTIFS(Applications!$B$2:$B$3144,A11,Applications!$F$2:$F$3144,"Offered") -> 0 | O11: =IF(COUNTIFS(Applications!$B$2:$B$3144,A11,Applications!$H$2:$H$3144,"Yes")>0,"Yes","No") -> No | P11: =SUMIFS(Applications!$G$2:$G$3144,Applications!$B$2:$B$3144,A11,Applications!$H$2:$H$3144,"Yes") -> 0 | Q11: =IF(O11="Yes",INDEX(Companies!$B$2:$B$31,MATCH(INDEX(Applications!$C$2:$C$3144,MATCH(A11,Applications!$P$2:$P$3144,0)),Companies!$A$2:$A$31,0)),"-") -> -
A12: S0011 | B12: Rohan Nair | C12: Batch 2024 | D12: Data Analytics | E12: Tier 1 | F12: 8.82 | G12: 82 | H12: 4 | I12: No | J12: 47 | K12: =ROUND(Assumptions!$B$4*MIN(G12/Assumptions!$B$11,1)*100+Assumptions!$B$5*F12/10*100+Assumptions!$B$6*MIN(H12/Assumptions!$B$12,1)*100+Assumptions!$B$7*J12+Assumptions!$B$8*IF(I12="Yes",100,0),1) -> 48 | L12: =LOOKUP(K12,Assumptions!$D$4:$D$7,Assumptions!$E$4:$E$7) -> Foundation | M12: =COUNTIFS(Applications!$B$2:$B$3144,A12) -> 6 | N12: =COUNTIFS(Applications!$B$2:$B$3144,A12,Applications!$F$2:$F$3144,"Offered") -> 0 | O12: =IF(COUNTIFS(Applications!$B$2:$B$3144,A12,Applications!$H$2:$H$3144,"Yes")>0,"Yes","No") -> No | P12: =SUMIFS(Applications!$G$2:$G$3144,Applications!$B$2:$B$3144,A12,Applications!$H$2:$H$3144,"Yes") -> 0 | Q12: =IF(O12="Yes",INDEX(Companies!$B$2:$B$31,MATCH(INDEX(Applications!$C$2:$C$3144,MATCH(A12,Applications!$P$2:$P$3144,0)),Companies!$A$2:$A$31,0)),"-") -> -
A13: S0012 | B13: Aditya Gupta | C13: Batch 2024 | D13: DSA with Java | E13: Tier 2 | F13: 9.8 | G13: 587 | H13: 3 | I13: No | J13: 60 | K13: =ROUND(Assumptions!$B$4*MIN(G13/Assumptions!$B$11,1)*100+Assumptions!$B$5*F13/10*100+Assumptions!$B$6*MIN(H13/Assumptions!$B$12,1)*100+Assumptions!$B$7*J13+Assumptions!$B$8*IF(I13="Yes",100,0),1) -> 73.6 | L13: =LOOKUP(K13,Assumptions!$D$4:$D$7,Assumptions!$E$4:$E$7) -> Job-Ready | M13: =COUNTIFS(Applications!$B$2:$B$3144,A13) -> 6 | N13: =COUNTIFS(Applications!$B$2:$B$3144,A13,Applications!$F$2:$F$3144,"Offered") -> 5 | O13: =IF(COUNTIFS(Applications!$B$2:$B$3144,A13,Applications!$H$2:$H$3144,"Yes")>0,"Yes","No") -> Yes | P13: =SUMIFS(Applications!$G$2:$G$3144,Applications!$B$2:$B$3144,A13,Applications!$H$2:$H$3144,"Yes") -> 12.1 | Q13: =IF(O13="Yes",INDEX(Companies!$B$2:$B$31,MATCH(INDEX(Applications!$C$2:$C$3144,MATCH(A13,Applications!$P$2:$P$3144,0)),Companies!$A$2:$A$31,0)),"-") -> LearnLoop
... A601: S0600 | B601: Arjun Mehta | C601: Batch 2026 | D601: Data Science & ML | E601: Tier 3 | F601: 7.57 | G601: 417 | H601: 1 | I601: No | J601: 54 | K601: =ROUND(Assumptions!$B$4*MIN(G601/Assumptions!$B$11,1)*100+Assumptions!$B$5*F601/10*100+Assumptions!$B$6*MIN(H601/Assumptions!$B$12,1)*100+Assumptions!$B$7*J601+Assumptions!$B$8*IF(I601="Yes",100,0),1) -> 55 | L601: =LOOKUP(K601,Assumptions!$D$4:$D$7,Assumptions!$E$4:$E$7) -> Developing | M601: =COUNTIFS(Applications!$B$2:$B$3144,A601) -> 3 | N601: =COUNTIFS(Applications!$B$2:$B$3144,A601,Applications!$F$2:$F$3144,"Offered") -> 1 | O601: =IF(COUNTIFS(Applications!$B$2:$B$3144,A601,Applications!$H$2:$H$3144,"Yes")>0,"Yes","No") -> Yes | P601: =SUMIFS(Applications!$G$2:$G$3144,Applications!$B$2:$B$3144,A601,Applications!$H$2:$H$3144,"Yes") -> 5.1 | Q601: =IF(O601="Yes",INDEX(Companies!$B$2:$B$31,MATCH(INDEX(Applications!$C$2:$C$3144,MATCH(A601,Applications!$P$2:$P$3144,0)),Companies!$A$2:$A$31,0)),"-") -> HealthLink Digital

Sheet Applications
A1: Application ID | B1: Student ID | C1: Company ID | D1: Role Applied | E1: Applied Date | F1: Stage Reached | G1: Offer CTC (LPA) | H1: Offer Accepted | I1: Offer Date | J1: Batch | K1: Course | L1: Sector | M1: Company Tier | N1: Stage No | O1: Offer Month | P1: Hire Key
A2: A00001 | B2: S0009 | C2: C06 | D2: Software Engineer | E2: 45139 | F2: Applied | J2: =INDEX(Students!$C$2:$C$601,MATCH(B2,Students!$A$2:$A$601,0)) -> Batch 2024 | K2: =INDEX(Students!$D$2:$D$601,MATCH(B2,Students!$A$2:$A$601,0)) -> Full Stack Development | L2: =INDEX(Companies!$C$2:$C$31,MATCH(C2,Companies!$A$2:$A$31,0)) -> Cybersecurity | M2: =INDEX(Companies!$D$2:$D$31,MATCH(C2,Companies!$A$2:$A$31,0)) -> Tier 1 | N2: =MATCH(F2,Assumptions!$K$4:$K$8,0) -> 1 | O2: =IF(H2="Yes",MONTH(I2),"") | P2: =IF(H2="Yes",B2,"")
A3: A00002 | B3: S0010 | C3: C20 | D3: Software Engineer | E3: 45139 | F3: Online Test | J3: =INDEX(Students!$C$2:$C$601,MATCH(B3,Students!$A$2:$A$601,0)) -> Batch 2024 | K3: =INDEX(Students!$D$2:$D$601,MATCH(B3,Students!$A$2:$A$601,0)) -> Full Stack Development | L3: =INDEX(Companies!$C$2:$C$31,MATCH(C3,Companies!$A$2:$A$31,0)) -> IT Services | M3: =INDEX(Companies!$D$2:$D$31,MATCH(C3,Companies!$A$2:$A$31,0)) -> Tier 3 | N3: =MATCH(F3,Assumptions!$K$4:$K$8,0) -> 2 | O3: =IF(H3="Yes",MONTH(I3),"") | P3: =IF(H3="Yes",B3,"")
A4: A00003 | B4: S0032 | C4: C25 | D4: Full Stack Developer | E4: 45139 | F4: Applied | J4: =INDEX(Students!$C$2:$C$601,MATCH(B4,Students!$A$2:$A$601,0)) -> Batch 2024 | K4: =INDEX(Students!$D$2:$D$601,MATCH(B4,Students!$A$2:$A$601,0)) -> Full Stack Development | L4: =INDEX(Companies!$C$2:$C$31,MATCH(C4,Companies!$A$2:$A$31,0)) -> IT Services | M4: =INDEX(Companies!$D$2:$D$31,MATCH(C4,Companies!$A$2:$A$31,0)) -> Tier 3 | N4: =MATCH(F4,Assumptions!$K$4:$K$8,0) -> 1 | O4: =IF(H4="Yes",MONTH(I4),"") | P4: =IF(H4="Yes",B4,"")
A5: A00004 | B5: S0055 | C5: C14 | D5: Backend Engineer | E5: 45141 | F5: Offered | G5: 10.5 | H5: No | I5: 45183 | J5: =INDEX(Students!$C$2:$C$601,MATCH(B5,Students!$A$2:$A$601,0)) -> Batch 2024 | K5: =INDEX(Students!$D$2:$D$601,MATCH(B5,Students!$A$2:$A$601,0)) -> DSA with Java | L5: =INDEX(Companies!$C$2:$C$31,MATCH(C5,Companies!$A$2:$A$31,0)) -> E-commerce | M5: =INDEX(Companies!$D$2:$D$31,MATCH(C5,Companies!$A$2:$A$31,0)) -> Tier 2 | N5: =MATCH(F5,Assumptions!$K$4:$K$8,0) -> 5 | O5: =IF(H5="Yes",MONTH(I5),"") | P5: =IF(H5="Yes",B5,"")
A6: A00005 | B6: S0133 | C6: C01 | D6: BI Analyst | E6: 45141 | F6: Applied | J6: =INDEX(Students!$C$2:$C$601,MATCH(B6,Students!$A$2:$A$601,0)) -> Batch 2024 | K6: =INDEX(Students!$D$2:$D$601,MATCH(B6,Students!$A$2:$A$601,0)) -> Data Analytics | L6: =INDEX(Companies!$C$2:$C$31,MATCH(C6,Companies!$A$2:$A$31,0)) -> Product | M6: =INDEX(Companies!$D$2:$D$31,MATCH(C6,Companies!$A$2:$A$31,0)) -> Tier 1 | N6: =MATCH(F6,Assumptions!$K$4:$K$8,0) -> 1 | O6: =IF(H6="Yes",MONTH(I6),"") | P6: =IF(H6="Yes",B6,"")
A7: A00006 | B7: S0056 | C7: C05 | D7: Software Development Engineer | E7: 45141 | F7: Online Test | J7: =INDEX(Students!$C$2:$C$601,MATCH(B7,Students!$A$2:$A$601,0)) -> Batch 2024 | K7: =INDEX(Students!$D$2:$D$601,MATCH(B7,Students!$A$2:$A$601,0)) -> DSA with Java | L7: =INDEX(Companies!$C$2:$C$31,MATCH(C7,Companies!$A$2:$A$31,0)) -> Analytics & Consulting | M7: =INDEX(Companies!$D$2:$D$31,MATCH(C7,Companies!$A$2:$A$31,0)) -> Tier 1 | N7: =MATCH(F7,Assumptions!$K$4:$K$8,0) -> 2 | O7: =IF(H7="Yes",MONTH(I7),"") | P7: =IF(H7="Yes",B7,"")
A8: A00007 | B8: S0173 | C8: C18 | D8: ML Engineer | E8: 45141 | F8: Offered | G8: 8.1 | H8: No | I8: 45181 | J8: =INDEX(Students!$C$2:$C$601,MATCH(B8,Students!$A$2:$A$601,0)) -> Batch 2024 | K8: =INDEX(Students!$D$2:$D$601,MATCH(B8,Students!$A$2:$A$601,0)) -> Data Science & ML | L8: =INDEX(Companies!$C$2:$C$31,MATCH(C8,Companies!$A$2:$A$31,0)) -> Analytics & Consulting | M8: =INDEX(Companies!$D$2:$D$31,MATCH(C8,Companies!$A$2:$A$31,0)) -> Tier 2 | N8: =MATCH(F8,Assumptions!$K$4:$K$8,0) -> 5 | O8: =IF(H8="Yes",MONTH(I8),"") | P8: =IF(H8="Yes",B8,"")
A9: A00008 | B9: S0014 | C9: C22 | D9: Full Stack Developer | E9: 45141 | F9: Technical Interview | J9: =INDEX(Students!$C$2:$C$601,MATCH(B9,Students!$A$2:$A$601,0)) -> Batch 2024 | K9: =INDEX(Students!$D$2:$D$601,MATCH(B9,Students!$A$2:$A$601,0)) -> Full Stack Development | L9: =INDEX(Companies!$C$2:$C$31,MATCH(C9,Companies!$A$2:$A$31,0)) -> IT Services | M9: =INDEX(Companies!$D$2:$D$31,MATCH(C9,Companies!$A$2:$A$31,0)) -> Tier 3 | N9: =MATCH(F9,Assumptions!$K$4:$K$8,0) -> 3 | O9: =IF(H9="Yes",MONTH(I9),"") | P9: =IF(H9="Yes",B9,"")
A10: A00009 | B10: S0129 | C10: C07 | D10: Full Stack Developer | E10: 45141 | F10: Offered | G10: 12.5 | H10: Yes | I10: 45191 | J10: =INDEX(Students!$C$2:$C$601,MATCH(B10,Students!$A$2:$A$601,0)) -> Batch 2024 | K10: =INDEX(Students!$D$2:$D$601,MATCH(B10,Students!$A$2:$A$601,0)) -> Full Stack Development | L10: =INDEX(Companies!$C$2:$C$31,MATCH(C10,Companies!$A$2:$A$31,0)) -> E-commerce | M10: =INDEX(Companies!$D$2:$D$31,MATCH(C10,Companies!$A$2:$A$31,0)) -> Tier 2 | N10: =MATCH(F10,Assumptions!$K$4:$K$8,0) -> 5 | O10: =IF(H10="Yes",MONTH(I10),"") -> 9 | P10: =IF(H10="Yes",B10,"") -> S0129
A11: A00010 | B11: S0156 | C11: C23 | D11: Full Stack Developer | E11: 45141 | F11: Applied | J11: =INDEX(Students!$C$2:$C$601,MATCH(B11,Students!$A$2:$A$601,0)) -> Batch 2024 | K11: =INDEX(Students!$D$2:$D$601,MATCH(B11,Students!$A$2:$A$601,0)) -> Full Stack Development | L11: =INDEX(Companies!$C$2:$C$31,MATCH(C11,Companies!$A$2:$A$31,0)) -> IT Services | M11: =INDEX(Companies!$D$2:$D$31,MATCH(C11,Companies!$A$2:$A$31,0)) -> Tier 3 | N11: =MATCH(F11,Assumptions!$K$4:$K$8,0) -> 1 | O11: =IF(H11="Yes",MONTH(I11),"") | P11: =IF(H11="Yes",B11,"")
A12: A00011 | B12: S0036 | C12: C09 | D12: Backend Engineer | E12: 45142 | F12: Technical Interview | J12: =INDEX(Students!$C$2:$C$601,MATCH(B12,Students!$A$2:$A$601,0)) -> Batch 2024 | K12: =INDEX(Students!$D$2:$D$601,MATCH(B12,Students!$A$2:$A$601,0)) -> DSA with Java | L12: =INDEX(Companies!$C$2:$C$31,MATCH(C12,Companies!$A$2:$A$31,0)) -> Healthtech | M12: =INDEX(Companies!$D$2:$D$31,MATCH(C12,Companies!$A$2:$A$31,0)) -> Tier 2 | N12: =MATCH(F12,Assumptions!$K$4:$K$8,0) -> 3 | O12: =IF(H12="Yes",MONTH(I12),"") | P12: =IF(H12="Yes",B12,"")
A13: A00012 | B13: S0034 | C13: C28 | D13: Software Development Engineer | E13: 45142 | F13: Applied | J13: =INDEX(Students!$C$2:$C$601,MATCH(B13,Students!$A$2:$A$601,0)) -> Batch 2024 | K13: =INDEX(Students!$D$2:$D$601,MATCH(B13,Students!$A$2:$A$601,0)) -> DSA with Java | L13: =INDEX(Companies!$C$2:$C$31,MATCH(C13,Companies!$A$2:$A$31,0)) -> Healthtech | M13: =INDEX(Companies!$D$2:$D$31,MATCH(C13,Companies!$A$2:$A$31,0)) -> Tier 3 | N13: =MATCH(F13,Assumptions!$K$4:$K$8,0) -> 1 | O13: =IF(H13="Yes",MONTH(I13),"") | P13: =IF(H13="Yes",B13,"")
A14: A00013 | B14: S0169 | C14: C23 | D14: Full Stack Developer | E14: 45142 | F14: Offered | G14: 5.1 | H14: No | I14: 45189 | J14: =INDEX(Students!$C$2:$C$601,MATCH(B14,Students!$A$2:$A$601,0)) -> Batch 2024 | K14: =INDEX(Students!$D$2:$D$601,MATCH(B14,Students!$A$2:$A$601,0)) -> Full Stack Development | L14: =INDEX(Companies!$C$2:$C$31,MATCH(C14,Companies!$A$2:$A$31,0)) -> IT Services | M14: =INDEX(Companies!$D$2:$D$31,MATCH(C14,Companies!$A$2:$A$31,0)) -> Tier 3 | N14: =MATCH(F14,Assumptions!$K$4:$K$8,0) -> 5 | O14: =IF(H14="Yes",MONTH(I14),"") | P14: =IF(H14="Yes",B14,"")
A15: A00014 | B15: S0180 | C15: C04 | D15: Data Analyst | E15: 45142 | F15: Applied | J15: =INDEX(Students!$C$2:$C$601,MATCH(B15,Students!$A$2:$A$601,0)) -> Batch 2024 | K15: =INDEX(Students!$D$2:$D$601,MATCH(B15,Students!$A$2:$A$601,0)) -> Data Analytics | L15: =INDEX(Companies!$C$2:$C$31,MATCH(C15,Companies!$A$2:$A$31,0)) -> E-commerce | M15: =INDEX(Companies!$D$2:$D$31,MATCH(C15,Companies!$A$2:$A$31,0)) -> Tier 1 | N15: =MATCH(F15,Assumptions!$K$4:$K$8,0) -> 1 | O15: =IF(H15="Yes",MONTH(I15),"") | P15: =IF(H15="Yes",B15,"")
A16: A00015 | B16: S0172 | C16: C30 | D16: Full Stack Developer | E16: 45143 | F16: Online Test | J16: =INDEX(Students!$C$2:$C$601,MATCH(B16,Students!$A$2:$A$601,0)) -> Batch 2024 | K16: =INDEX(Students!$D$2:$D$601,MATCH(B16,Students!$A$2:$A$601,0)) -> Full Stack Development | L16: =INDEX(Companies!$C$2:$C$31,MATCH(C16,Companies!$A$2:$A$31,0)) -> Analytics & Consulting | M16: =INDEX(Companies!$D$2:$D$31,MATCH(C16,Companies!$A$2:$A$31,0)) -> Tier 3 | N16: =MATCH(F16,Assumptions!$K$4:$K$8,0) -> 2 | O16: =IF(H16="Yes",MONTH(I16),"") | P16: =IF(H16="Yes",B16,"")
A17: A00016 | B17: S0178 | C17: C18 | D17: Software Engineer | E17: 45143 | F17: Offered | G17: 11 | H17: No | I17: 45174 | J17: =INDEX(Students!$C$2:$C$601,MATCH(B17,Students!$A$2:$A$601,0)) -> Batch 2024 | K17: =INDEX(Students!$D$2:$D$601,MATCH(B17,Students!$A$2:$A$601,0)) -> Full Stack Development | L17: =INDEX(Companies!$C$2:$C$31,MATCH(C17,Companies!$A$2:$A$31,0)) -> Analytics & Consulting | M17: =INDEX(Companies!$D$2:$D$31,MATCH(C17,Companies!$A$2:$A$31,0)) -> Tier 2 | N17: =MATCH(F17,Assumptions!$K$4:$K$8,0) -> 5 | O17: =IF(H17="Yes",MONTH(I17),"") | P17: =IF(H17="Yes",B17,"")
A18: A00017 | B18: S0107 | C18: C02 | D18: Software Development Engineer | E18: 45143 | F18: Online Test | J18: =INDEX(Students!$C$2:$C$601,MATCH(B18,Students!$A$2:$A$601,0)) -> Batch 2024 | K18: =INDEX(Students!$D$2:$D$601,MATCH(B18,Students!$A$2:$A$601,0)) -> DSA with Java | L18: =INDEX(Companies!$C$2:$C$31,MATCH(C18,Companies!$A$2:$A$31,0)) -> Product | M18: =INDEX(Companies!$D$2:$D$31,MATCH(C18,Companies!$A$2:$A$31,0)) -> Tier 1 | N18: =MATCH(F18,Assumptions!$K$4:$K$8,0) -> 2 | O18: =IF(H18="Yes",MONTH(I18),"") | P18: =IF(H18="Yes",B18,"")
A19: A00018 | B19: S0051 | C19: C19 | D19: Software Development Engineer | E19: 45143 | F19: Online Test | J19: =INDEX(Students!$C$2:$C$601,MATCH(B19,Students!$A$2:$A$601,0)) -> Batch 2024 | K19: =INDEX(Students!$D$2:$D$601,MATCH(B19,Students!$A$2:$A$601,0)) -> DSA with Java | L19: =INDEX(Companies!$C$2:$C$31,MATCH(C19,Companies!$A$2:$A$31,0)) -> IT Services | M19: =INDEX(Companies!$D$2:$D$31,MATCH(C19,Companies!$A$2:$A$31,0)) -> Tier 3 | N19: =MATCH(F19,Assumptions!$K$4:$K$8,0) -> 2 | O19: =IF(H19="Yes",MONTH(I19),"") | P19: =IF(H19="Yes",B19,"")
A20: A00019 | B20: S0015 | C20: C02 | D20: Full Stack Developer | E20: 45144 | F20: HR Interview | J20: =INDEX(Students!$C$2:$C$601,MATCH(B20,Students!$A$2:$A$601,0)) -> Batch 2024 | K20: =INDEX(Students!$D$2:$D$601,MATCH(B20,Students!$A$2:$A$601,0)) -> Full Stack Development | L20: =INDEX(Companies!$C$2:$C$31,MATCH(C20,Companies!$A$2:$A$31,0)) -> Product | M20: =INDEX(Companies!$D$2:$D$31,MATCH(C20,Companies!$A$2:$A$31,0)) -> Tier 1 | N20: =MATCH(F20,Assumptions!$K$4:$K$8,0) -> 4 | O20: =IF(H20="Yes",MONTH(I20),"") | P20: =IF(H20="Yes",B20,"")
A21: A00020 | B21: S0011 | C21: C22 | D21: Data Analyst | E21: 45145 | F21: Online Test | J21: =INDEX(Students!$C$2:$C$601,MATCH(B21,Students!$A$2:$A$601,0)) -> Batch 2024 | K21: =INDEX(Students!$D$2:$D$601,MATCH(B21,Students!$A$2:$A$601,0)) -> Data Analytics | L21: =INDEX(Companies!$C$2:$C$31,MATCH(C21,Companies!$A$2:$A$31,0)) -> IT Services | M21: =INDEX(Companies!$D$2:$D$31,MATCH(C21,Companies!$A$2:$A$31,0)) -> Tier 3 | N21: =MATCH(F21,Assumptions!$K$4:$K$8,0) -> 2 | O21: =IF(H21="Yes",MONTH(I21),"") | P21: =IF(H21="Yes",B21,"")
A22: A00021 | B22: S0027 | C22: C14 | D22: Backend Engineer | E22: 45146 | F22: Applied | J22: =INDEX(Students!$C$2:$C$601,MATCH(B22,Students!$A$2:$A$601,0)) -> Batch 2024 | K22: =INDEX(Students!$D$2:$D$601,MATCH(B22,Students!$A$2:$A$601,0)) -> DSA with Java | L22: =INDEX(Companies!$C$2:$C$31,MATCH(C22,Companies!$A$2:$A$31,0)) -> E-commerce | M22: =INDEX(Companies!$D$2:$D$31,MATCH(C22,Companies!$A$2:$A$31,0)) -> Tier 2 | N22: =MATCH(F22,Assumptions!$K$4:$K$8,0) -> 1 | O22: =IF(H22="Yes",MONTH(I22),"") | P22: =IF(H22="Yes",B22,"")
A23: A00022 | B23: S0047 | C23: C12 | D23: BI Analyst | E23: 45146 | F23: Technical Interview | J23: =INDEX(Students!$C$2:$C$601,MATCH(B23,Students!$A$2:$A$601,0)) -> Batch 2024 | K23: =INDEX(Students!$D$2:$D$601,MATCH(B23,Students!$A$2:$A$601,0)) -> Data Analytics | L23: =INDEX(Companies!$C$2:$C$31,MATCH(C23,Companies!$A$2:$A$31,0)) -> Product | M23: =INDEX(Companies!$D$2:$D$31,MATCH(C23,Companies!$A$2:$A$31,0)) -> Tier 2 | N23: =MATCH(F23,Assumptions!$K$4:$K$8,0) -> 3 | O23: =IF(H23="Yes",MONTH(I23),"") | P23: =IF(H23="Yes",B23,"")
A24: A00023 | B24: S0060 | C24: C20 | D24: Full Stack Developer | E24: 45146 | F24: Offered | G24: 5.4 | H24: No | I24: 45180 | J24: =INDEX(Students!$C$2:$C$601,MATCH(B24,Students!$A$2:$A$601,0)) -> Batch 2024 | K24: =INDEX(Students!$D$2:$D$601,MATCH(B24,Students!$A$2:$A$601,0)) -> Full Stack Development | L24: =INDEX(Companies!$C$2:$C$31,MATCH(C24,Companies!$A$2:$A$31,0)) -> IT Services | M24: =INDEX(Companies!$D$2:$D$31,MATCH(C24,Companies!$A$2:$A$31,0)) -> Tier 3 | N24: =MATCH(F24,Assumptions!$K$4:$K$8,0) -> 5 | O24: =IF(H24="Yes",MONTH(I24),"") | P24: =IF(H24="Yes",B24,"")
A25: A00024 | B25: S0017 | C25: C08 | D25: SOC Analyst | E25: 45146 | F25: Online Test | J25: =INDEX(Students!$C$2:$C$601,MATCH(B25,Students!$A$2:$A$601,0)) -> Batch 2024 | K25: =INDEX(Students!$D$2:$D$601,MATCH(B25,Students!$A$2:$A$601,0)) -> Cybersecurity | L25: =INDEX(Companies!$C$2:$C$31,MATCH(C25,Companies!$A$2:$A$31,0)) -> EdTech | M25: =INDEX(Companies!$D$2:$D$31,MATCH(C25,Companies!$A$2:$A$31,0)) -> Tier 2 | N25: =MATCH(F25,Assumptions!$K$4:$K$8,0) -> 2 | O25: =IF(H25="Yes",MONTH(I25),"") | P25: =IF(H25="Yes",B25,"")
A26: A00025 | B26: S0147 | C26: C03 | D26: Software Development Engineer | E26: 45146 | F26: Applied | J26: =INDEX(Students!$C$2:$C$601,MATCH(B26,Students!$A$2:$A$601,0)) -> Batch 2024 | K26: =INDEX(Students!$D$2:$D$601,MATCH(B26,Students!$A$2:$A$601,0)) -> DSA with Java | L26: =INDEX(Companies!$C$2:$C$31,MATCH(C26,Companies!$A$2:$A$31,0)) -> Fintech | M26: =INDEX(Companies!$D$2:$D$31,MATCH(C26,Companies!$A$2:$A$31,0)) -> Tier 1 | N26: =MATCH(F26,Assumptions!$K$4:$K$8,0) -> 1 | O26: =IF(H26="Yes",MONTH(I26),"") | P26: =IF(H26="Yes",B26,"")
A27: A00026 | B27: S0014 | C27: C26 | D27: Software Engineer | E27: 45146 | F27: Online Test | J27: =INDEX(Students!$C$2:$C$601,MATCH(B27,Students!$A$2:$A$601,0)) -> Batch 2024 | K27: =INDEX(Students!$D$2:$D$601,MATCH(B27,Students!$A$2:$A$601,0)) -> Full Stack Development | L27: =INDEX(Companies!$C$2:$C$31,MATCH(C27,Companies!$A$2:$A$31,0)) -> IT Services | M27: =INDEX(Companies!$D$2:$D$31,MATCH(C27,Companies!$A$2:$A$31,0)) -> Tier 3 | N27: =MATCH(F27,Assumptions!$K$4:$K$8,0) -> 2 | O27: =IF(H27="Yes",MONTH(I27),"") | P27: =IF(H27="Yes",B27,"")
A28: A00027 | B28: S0037 | C28: C07 | D28: BI Analyst | E28: 45146 | F28: Applied | J28: =INDEX(Students!$C$2:$C$601,MATCH(B28,Students!$A$2:$A$601,0)) -> Batch 2024 | K28: =INDEX(Students!$D$2:$D$601,MATCH(B28,Students!$A$2:$A$601,0)) -> Data Analytics | L28: =INDEX(Companies!$C$2:$C$31,MATCH(C28,Companies!$A$2:$A$31,0)) -> E-commerce | M28: =INDEX(Companies!$D$2:$D$31,MATCH(C28,Companies!$A$2:$A$31,0)) -> Tier 2 | N28: =MATCH(F28,Assumptions!$K$4:$K$8,0) -> 1 | O28: =IF(H28="Yes",MONTH(I28),"") | P28: =IF(H28="Yes",B28,"")
A29: A00028 | B29: S0030 | C29: C04 | D29: SOC Analyst | E29: 45146 | F29: Online Test | J29: =INDEX(Students!$C$2:$C$601,MATCH(B29,Students!$A$2:$A$601,0)) -> Batch 2024 | K29: =INDEX(Students!$D$2:$D$601,MATCH(B29,Students!$A$2:$A$601,0)) -> Cybersecurity | L29: =INDEX(Companies!$C$2:$C$31,MATCH(C29,Companies!$A$2:$A$31,0)) -> E-commerce | M29: =INDEX(Companies!$D$2:$D$31,MATCH(C29,Companies!$A$2:$A$31,0)) -> Tier 1 | N29: =MATCH(F29,Assumptions!$K$4:$K$8,0) -> 2 | O29: =IF(H29="Yes",MONTH(I29),"") | P29: =IF(H29="Yes",B29,"")
A30: A00029 | B30: S0148 | C30: C27 | D30: Backend Engineer | E30: 45146 | F30: Offered | G30: 6.3 | H30: No | I30: 45195 | J30: =INDEX(Students!$C$2:$C$601,MATCH(B30,Students!$A$2:$A$601,0)) -> Batch 2024 | K30: =INDEX(Students!$D$2:$D$601,MATCH(B30,Students!$A$2:$A$601,0)) -> DSA with Java | L30: =INDEX(Companies!$C$2:$C$31,MATCH(C30,Companies!$A$2:$A$31,0)) -> EdTech | M30: =INDEX(Companies!$D$2:$D$31,MATCH(C30,Companies!$A$2:$A$31,0)) -> Tier 3 | N30: =MATCH(F30,Assumptions!$K$4:$K$8,0) -> 5 | O30: =IF(H30="Yes",MONTH(I30),"") | P30: =IF(H30="Yes",B30,"")
A31: A00030 | B31: S0060 | C31: C12 | D31: Software Engineer | E31: 45147 | F31: Online Test | J31: =INDEX(Students!$C$2:$C$601,MATCH(B31,Students!$A$2:$A$601,0)) -> Batch 2024 | K31: =INDEX(Students!$D$2:$D$601,MATCH(B31,Students!$A$2:$A$601,0)) -> Full Stack Development | L31: =INDEX(Companies!$C$2:$C$31,MATCH(C31,Companies!$A$2:$A$31,0)) -> Product | M31: =INDEX(Companies!$D$2:$D$31,MATCH(C31,Companies!$A$2:$A$31,0)) -> Tier 2 | N31: =MATCH(F31,Assumptions!$K$4:$K$8,0) -> 2 | O31: =IF(H31="Yes",MONTH(I31),"") | P31: =IF(H31="Yes",B31,"")
A32: A00031 | B32: S0012 | C32: C05 | D32: Software Development Engineer | E32: 45147 | F32: Online Test | J32: =INDEX(Students!$C$2:$C$601,MATCH(B32,Students!$A$2:$A$601,0)) -> Batch 2024 | K32: =INDEX(Students!$D$2:$D$601,MATCH(B32,Students!$A$2:$A$601,0)) -> DSA with Java | L32: =INDEX(Companies!$C$2:$C$31,MATCH(C32,Companies!$A$2:$A$31,0)) -> Analytics & Consulting | M32: =INDEX(Companies!$D$2:$D$31,MATCH(C32,Companies!$A$2:$A$31,0)) -> Tier 1 | N32: =MATCH(F32,Assumptions!$K$4:$K$8,0) -> 2 | O32: =IF(H32="Yes",MONTH(I32),"") | P32: =IF(H32="Yes",B32,"")
A33: A00032 | B33: S0090 | C33: C27 | D33: Data Analyst | E33: 45148 | F33: Technical Interview | J33: =INDEX(Students!$C$2:$C$601,MATCH(B33,Students!$A$2:$A$601,0)) -> Batch 2024 | K33: =INDEX(Students!$D$2:$D$601,MATCH(B33,Students!$A$2:$A$601,0)) -> Data Analytics | L33: =INDEX(Companies!$C$2:$C$31,MATCH(C33,Companies!$A$2:$A$31,0)) -> EdTech | M33: =INDEX(Companies!$D$2:$D$31,MATCH(C33,Companies!$A$2:$A$31,0)) -> Tier 3 | N33: =MATCH(F33,Assumptions!$K$4:$K$8,0) -> 3 | O33: =IF(H33="Yes",MONTH(I33),"") | P33: =IF(H33="Yes",B33,"")
A34: A00033 | B34: S0017 | C34: C29 | D34: Security Analyst | E34: 45148 | F34: HR Interview | J34: =INDEX(Students!$C$2:$C$601,MATCH(B34,Students!$A$2:$A$601,0)) -> Batch 2024 | K34: =INDEX(Students!$D$2:$D$601,MATCH(B34,Students!$A$2:$A$601,0)) -> Cybersecurity | L34: =INDEX(Companies!$C$2:$C$31,MATCH(C34,Companies!$A$2:$A$31,0)) -> E-commerce | M34: =INDEX(Companies!$D$2:$D$31,MATCH(C34,Companies!$A$2:$A$31,0)) -> Tier 3 | N34: =MATCH(F34,Assumptions!$K$4:$K$8,0) -> 4 | O34: =IF(H34="Yes",MONTH(I34),"") | P34: =IF(H34="Yes",B34,"")
A35: A00034 | B35: S0115 | C35: C04 | D35: Software Engineer | E35: 45148 | F35: Offered | G35: 26 | H35: No | I35: 45190 | J35: =INDEX(Students!$C$2:$C$601,MATCH(B35,Students!$A$2:$A$601,0)) -> Batch 2024 | K35: =INDEX(Students!$D$2:$D$601,MATCH(B35,Students!$A$2:$A$601,0)) -> Full Stack Development | L35: =INDEX(Companies!$C$2:$C$31,MATCH(C35,Companies!$A$2:$A$31,0)) -> E-commerce | M35: =INDEX(Companies!$D$2:$D$31,MATCH(C35,Companies!$A$2:$A$31,0)) -> Tier 1 | N35: =MATCH(F35,Assumptions!$K$4:$K$8,0) -> 5 | O35: =IF(H35="Yes",MONTH(I35),"") | P35: =IF(H35="Yes",B35,"")
A36: A00035 | B36: S0167 | C36: C30 | D36: Data Scientist | E36: 45148 | F36: Applied | J36: =INDEX(Students!$C$2:$C$601,MATCH(B36,Students!$A$2:$A$601,0)) -> Batch 2024 | K36: =INDEX(Students!$D$2:$D$601,MATCH(B36,Students!$A$2:$A$601,0)) -> Data Science & ML | L36: =INDEX(Companies!$C$2:$C$31,MATCH(C36,Companies!$A$2:$A$31,0)) -> Analytics & Consulting | M36: =INDEX(Companies!$D$2:$D$31,MATCH(C36,Companies!$A$2:$A$31,0)) -> Tier 3 | N36: =MATCH(F36,Assumptions!$K$4:$K$8,0) -> 1 | O36: =IF(H36="Yes",MONTH(I36),"") | P36: =IF(H36="Yes",B36,"")
A37: A00036 | B37: S0093 | C37: C18 | D37: Data Analyst | E37: 45149 | F37: Applied | J37: =INDEX(Students!$C$2:$C$601,MATCH(B37,Students!$A$2:$A$601,0)) -> Batch 2024 | K37: =INDEX(Students!$D$2:$D$601,MATCH(B37,Students!$A$2:$A$601,0)) -> Data Analytics | L37: =INDEX(Companies!$C$2:$C$31,MATCH(C37,Companies!$A$2:$A$31,0)) -> Analytics & Consulting | M37: =INDEX(Companies!$D$2:$D$31,MATCH(C37,Companies!$A$2:$A$31,0)) -> Tier 2 | N37: =MATCH(F37,Assumptions!$K$4:$K$8,0) -> 1 | O37: =IF(H37="Yes",MONTH(I37),"") | P37: =IF(H37="Yes",B37,"")
A38: A00037 | B38: S0110 | C38: C27 | D38: Backend Engineer | E38: 45149 | F38: Applied | J38: =INDEX(Students!$C$2:$C$601,MATCH(B38,Students!$A$2:$A$601,0)) -> Batch 2024 | K38: =INDEX(Students!$D$2:$D$601,MATCH(B38,Students!$A$2:$A$601,0)) -> DSA with Java | L38: =INDEX(Companies!$C$2:$C$31,MATCH(C38,Companies!$A$2:$A$31,0)) -> EdTech | M38: =INDEX(Companies!$D$2:$D$31,MATCH(C38,Companies!$A$2:$A$31,0)) -> Tier 3 | N38: =MATCH(F38,Assumptions!$K$4:$K$8,0) -> 1 | O38: =IF(H38="Yes",MONTH(I38),"") | P38: =IF(H38="Yes",B38,"")
A39: A00038 | B39: S0102 | C39: C22 | D39: Full Stack Developer | E39: 45149 | F39: Technical Interview | J39: =INDEX(Students!$C$2:$C$601,MATCH(B39,Students!$A$2:$A$601,0)) -> Batch 2024 | K39: =INDEX(Students!$D$2:$D$601,MATCH(B39,Students!$A$2:$A$601,0)) -> Full Stack Development | L39: =INDEX(Companies!$C$2:$C$31,MATCH(C39,Companies!$A$2:$A$31,0)) -> IT Services | M39: =INDEX(Companies!$D$2:$D$31,MATCH(C39,Companies!$A$2:$A$31,0)) -> Tier 3 | N39: =MATCH(F39,Assumptions!$K$4:$K$8,0) -> 3 | O39: =IF(H39="Yes",MONTH(I39),"") | P39: =IF(H39="Yes",B39,"")
A40: A00039 | B40: S0167 | C40: C25 | D40: Data Scientist | E40: 45149 | F40: Online Test | J40: =INDEX(Students!$C$2:$C$601,MATCH(B40,Students!$A$2:$A$601,0)) -> Batch 2024 | K40: =INDEX(Students!$D$2:$D$601,MATCH(B40,Students!$A$2:$A$601,0)) -> Data Science & ML | L40: =INDEX(Companies!$C$2:$C$31,MATCH(C40,Companies!$A$2:$A$31,0)) -> IT Services | M40: =INDEX(Companies!$D$2:$D$31,MATCH(C40,Companies!$A$2:$A$31,0)) -> Tier 3 | N40: =MATCH(F40,Assumptions!$K$4:$K$8,0) -> 2 | O40: =IF(H40="Yes",MONTH(I40),"") | P40: =IF(H40="Yes",B40,"")
...

Sheet Companies
A1: Company ID | B1: Company Name | C1: Sector | D1: Tier | E1: HQ City | F1: Applications | G1: Offers Made | H1: Hires | I1: Offer-to-Hire % | J1: Avg CTC (LPA) | K1: Rank Key | M1: Note: Applications / Offers / Hires respond to the Batch selector on the Dashboard.
A2: C01 | B2: Nimbus Cloud Systems | C2: Product | D2: Tier 1 | E2: Bengaluru | F2: =COUNTIFS(Applications!$C$2:$C$3144,A2,Applications!$J$2:$J$3144,Analysis!$B$2) -> 80 | G2: =COUNTIFS(Applications!$C$2:$C$3144,A2,Applications!$F$2:$F$3144,"Offered",Applications!$J$2:$J$3144,Analysis!$B$2) -> 10 | H2: =COUNTIFS(Applications!$C$2:$C$3144,A2,Applications!$H$2:$H$3144,"Yes",Applications!$J$2:$J$3144,Analysis!$B$2) -> 8 | I2: =IF(G2=0,0,H2/G2) -> 0.8 | J2: =IFERROR(AVERAGEIFS(Applications!$G$2:$G$3144,Applications!$C$2:$C$3144,A2,Applications!$H$2:$H$3144,"Yes",Applications!$J$2:$J$3144,Analysis!$B$2),0) -> 25.6375 | K2: =H2-ROW()/100000 -> 7.99998
A3: C02 | B3: Quantora Labs | C3: Product | D3: Tier 1 | E3: Hyderabad | F3: =COUNTIFS(Applications!$C$2:$C$3144,A3,Applications!$J$2:$J$3144,Analysis!$B$2) -> 86 | G3: =COUNTIFS(Applications!$C$2:$C$3144,A3,Applications!$F$2:$F$3144,"Offered",Applications!$J$2:$J$3144,Analysis!$B$2) -> 6 | H3: =COUNTIFS(Applications!$C$2:$C$3144,A3,Applications!$H$2:$H$3144,"Yes",Applications!$J$2:$J$3144,Analysis!$B$2) -> 5 | I3: =IF(G3=0,0,H3/G3) -> 0.83333333 | J3: =IFERROR(AVERAGEIFS(Applications!$G$2:$G$3144,Applications!$C$2:$C$3144,A3,Applications!$H$2:$H$3144,"Yes",Applications!$J$2:$J$3144,Analysis!$B$2),0) -> 20.96 | K3: =H3-ROW()/100000 -> 4.99997
A4: C03 | B4: Zenith Pay | C4: Fintech | D4: Tier 1 | E4: Mumbai | F4: =COUNTIFS(Applications!$C$2:$C$3144,A4,Applications!$J$2:$J$3144,Analysis!$B$2) -> 70 | G4: =COUNTIFS(Applications!$C$2:$C$3144,A4,Applications!$F$2:$F$3144,"Offered",Applications!$J$2:$J$3144,Analysis!$B$2) -> 13 | H4: =COUNTIFS(Applications!$C$2:$C$3144,A4,Applications!$H$2:$H$3144,"Yes",Applications!$J$2:$J$3144,Analysis!$B$2) -> 13 | I4: =IF(G4=0,0,H4/G4) -> 1 | J4: =IFERROR(AVERAGEIFS(Applications!$G$2:$G$3144,Applications!$C$2:$C$3144,A4,Applications!$H$2:$H$3144,"Yes",Applications!$J$2:$J$3144,Analysis!$B$2),0) -> 24.215385 | K4: =H4-ROW()/100000 -> 12.99996
A5: C04 | B5: Orbitly | C5: E-commerce | D5: Tier 1 | E5: Bengaluru | F5: =COUNTIFS(Applications!$C$2:$C$3144,A5,Applications!$J$2:$J$3144,Analysis!$B$2) -> 67 | G5: =COUNTIFS(Applications!$C$2:$C$3144,A5,Applications!$F$2:$F$3144,"Offered",Applications!$J$2:$J$3144,Analysis!$B$2) -> 9 | H5: =COUNTIFS(Applications!$C$2:$C$3144,A5,Applications!$H$2:$H$3144,"Yes",Applications!$J$2:$J$3144,Analysis!$B$2) -> 7 | I5: =IF(G5=0,0,H5/G5) -> 0.77777778 | J5: =IFERROR(AVERAGEIFS(Applications!$G$2:$G$3144,Applications!$C$2:$C$3144,A5,Applications!$H$2:$H$3144,"Yes",Applications!$J$2:$J$3144,Analysis!$B$2),0) -> 24.3 | K5: =H5-ROW()/100000 -> 6.99995
A6: C05 | B6: Vertex AI Works | C6: Analytics & Consulting | D6: Tier 1 | E6: Bengaluru | F6: =COUNTIFS(Applications!$C$2:$C$3144,A6,Applications!$J$2:$J$3144,Analysis!$B$2) -> 73 | G6: =COUNTIFS(Applications!$C$2:$C$3144,A6,Applications!$F$2:$F$3144,"Offered",Applications!$J$2:$J$3144,Analysis!$B$2) -> 4 | H6: =COUNTIFS(Applications!$C$2:$C$3144,A6,Applications!$H$2:$H$3144,"Yes",Applications!$J$2:$J$3144,Analysis!$B$2) -> 4 | I6: =IF(G6=0,0,H6/G6) -> 1 | J6: =IFERROR(AVERAGEIFS(Applications!$G$2:$G$3144,Applications!$C$2:$C$3144,A6,Applications!$H$2:$H$3144,"Yes",Applications!$J$2:$J$3144,Analysis!$B$2),0) -> 21.3 | K6: =H6-ROW()/100000 -> 3.99994
A7: C06 | B7: HelixSecure | C7: Cybersecurity | D7: Tier 1 | E7: Pune | F7: =COUNTIFS(Applications!$C$2:$C$3144,A7,Applications!$J$2:$J$3144,Analysis!$B$2) -> 67 | G7: =COUNTIFS(Applications!$C$2:$C$3144,A7,Applications!$F$2:$F$3144,"Offered",Applications!$J$2:$J$3144,Analysis!$B$2) -> 2 | H7: =COUNTIFS(Applications!$C$2:$C$3144,A7,Applications!$H$2:$H$3144,"Yes",Applications!$J$2:$J$3144,Analysis!$B$2) -> 2 | I7: =IF(G7=0,0,H7/G7) -> 1 | J7: =IFERROR(AVERAGEIFS(Applications!$G$2:$G$3144,Applications!$C$2:$C$3144,A7,Applications!$H$2:$H$3144,"Yes",Applications!$J$2:$J$3144,Analysis!$B$2),0) -> 24.3 | K7: =H7-ROW()/100000 -> 1.99993
A8: C07 | B8: CartNest | C8: E-commerce | D8: Tier 2 | E8: Gurugram | F8: =COUNTIFS(Applications!$C$2:$C$3144,A8,Applications!$J$2:$J$3144,Analysis!$B$2) -> 93 | G8: =COUNTIFS(Applications!$C$2:$C$3144,A8,Applications!$F$2:$F$3144,"Offered",Applications!$J$2:$J$3144,Analysis!$B$2) -> 26 | H8: =COUNTIFS(Applications!$C$2:$C$3144,A8,Applications!$H$2:$H$3144,"Yes",Applications!$J$2:$J$3144,Analysis!$B$2) -> 12 | I8: =IF(G8=0,0,H8/G8) -> 0.46153846 | J8: =IFERROR(AVERAGEIFS(Applications!$G$2:$G$3144,Applications!$C$2:$C$3144,A8,Applications!$H$2:$H$3144,"Yes",Applications!$J$2:$J$3144,Analysis!$B$2),0) -> 11.891667 | K8: =H8-ROW()/100000 -> 11.99992
A9: C08 | B9: LearnLoop | C9: EdTech | D9: Tier 2 | E9: Noida | F9: =COUNTIFS(Applications!$C$2:$C$3144,A9,Applications!$J$2:$J$3144,Analysis!$B$2) -> 92 | G9: =COUNTIFS(Applications!$C$2:$C$3144,A9,Applications!$F$2:$F$3144,"Offered",Applications!$J$2:$J$3144,Analysis!$B$2) -> 17 | H9: =COUNTIFS(Applications!$C$2:$C$3144,A9,Applications!$H$2:$H$3144,"Yes",Applications!$J$2:$J$3144,Analysis!$B$2) -> 11 | I9: =IF(G9=0,0,H9/G9) -> 0.64705882 | J9: =IFERROR(AVERAGEIFS(Applications!$G$2:$G$3144,Applications!$C$2:$C$3144,A9,Applications!$H$2:$H$3144,"Yes",Applications!$J$2:$J$3144,Analysis!$B$2),0) -> 11.9 | K9: =H9-ROW()/100000 -> 10.99991
A10: C09 | B10: MediSphere | C10: Healthtech | D10: Tier 2 | E10: Bengaluru | F10: =COUNTIFS(Applications!$C$2:$C$3144,A10,Applications!$J$2:$J$3144,Analysis!$B$2) -> 98 | G10: =COUNTIFS(Applications!$C$2:$C$3144,A10,Applications!$F$2:$F$3144,"Offered",Applications!$J$2:$J$3144,Analysis!$B$2) -> 19 | H10: =COUNTIFS(Applications!$C$2:$C$3144,A10,Applications!$H$2:$H$3144,"Yes",Applications!$J$2:$J$3144,Analysis!$B$2) -> 15 | I10: =IF(G10=0,0,H10/G10) -> 0.78947368 | J10: =IFERROR(AVERAGEIFS(Applications!$G$2:$G$3144,Applications!$C$2:$C$3144,A10,Applications!$H$2:$H$3144,"Yes",Applications!$J$2:$J$3144,Analysis!$B$2),0) -> 12.326667 | K10: =H10-ROW()/100000 -> 14.9999
A11: C10 | B11: FinStack | C11: Fintech | D11: Tier 2 | E11: Pune | F11: =COUNTIFS(Applications!$C$2:$C$3144,A11,Applications!$J$2:$J$3144,Analysis!$B$2) -> 114 | G11: =COUNTIFS(Applications!$C$2:$C$3144,A11,Applications!$F$2:$F$3144,"Offered",Applications!$J$2:$J$3144,Analysis!$B$2) -> 30 | H11: =COUNTIFS(Applications!$C$2:$C$3144,A11,Applications!$H$2:$H$3144,"Yes",Applications!$J$2:$J$3144,Analysis!$B$2) -> 19 | I11: =IF(G11=0,0,H11/G11) -> 0.63333333 | J11: =IFERROR(AVERAGEIFS(Applications!$G$2:$G$3144,Applications!$C$2:$C$3144,A11,Applications!$H$2:$H$3144,"Yes",Applications!$J$2:$J$3144,Analysis!$B$2),0) -> 12.536842 | K11: =H11-ROW()/100000 -> 18.99989
A12: C11 | B12: DataBridge Analytics | C12: Analytics & Consulting | D12: Tier 2 | E12: Hyderabad | F12: =COUNTIFS(Applications!$C$2:$C$3144,A12,Applications!$J$2:$J$3144,Analysis!$B$2) -> 96 | G12: =COUNTIFS(Applications!$C$2:$C$3144,A12,Applications!$F$2:$F$3144,"Offered",Applications!$J$2:$J$3144,Analysis!$B$2) -> 20 | H12: =COUNTIFS(Applications!$C$2:$C$3144,A12,Applications!$H$2:$H$3144,"Yes",Applications!$J$2:$J$3144,Analysis!$B$2) -> 13 | I12: =IF(G12=0,0,H12/G12) -> 0.65 | J12: =IFERROR(AVERAGEIFS(Applications!$G$2:$G$3144,Applications!$C$2:$C$3144,A12,Applications!$H$2:$H$3144,"Yes",Applications!$J$2:$J$3144,Analysis!$B$2),0) -> 11.730769 | K12: =H12-ROW()/100000 -> 12.99988
A13: C12 | B13: CloudKraft | C13: Product | D13: Tier 2 | E13: Chennai | F13: =COUNTIFS(Applications!$C$2:$C$3144,A13,Applications!$J$2:$J$3144,Analysis!$B$2) -> 105 | G13: =COUNTIFS(Applications!$C$2:$C$3144,A13,Applications!$F$2:$F$3144,"Offered",Applications!$J$2:$J$3144,Analysis!$B$2) -> 19 | H13: =COUNTIFS(Applications!$C$2:$C$3144,A13,Applications!$H$2:$H$3144,"Yes",Applications!$J$2:$J$3144,Analysis!$B$2) -> 15 | I13: =IF(G13=0,0,H13/G13) -> 0.78947368 | J13: =IFERROR(AVERAGEIFS(Applications!$G$2:$G$3144,Applications!$C$2:$C$3144,A13,Applications!$H$2:$H$3144,"Yes",Applications!$J$2:$J$3144,Analysis!$B$2),0) -> 11.793333 | K13: =H13-ROW()/100000 -> 14.99987
... A31: C30 | B31: DataHarbor | C31: Analytics & Consulting | D31: Tier 3 | E31: Pune | F31: =COUNTIFS(Applications!$C$2:$C$3144,A31,Applications!$J$2:$J$3144,Analysis!$B$2) -> 111 | G31: =COUNTIFS(Applications!$C$2:$C$3144,A31,Applications!$F$2:$F$3144,"Offered",Applications!$J$2:$J$3144,Analysis!$B$2) -> 48 | H31: =COUNTIFS(Applications!$C$2:$C$3144,A31,Applications!$H$2:$H$3144,"Yes",Applications!$J$2:$J$3144,Analysis!$B$2) -> 16 | I31: =IF(G31=0,0,H31/G31) -> 0.33333333 | J31: =IFERROR(AVERAGEIFS(Applications!$G$2:$G$3144,Applications!$C$2:$C$3144,A31,Applications!$H$2:$H$3144,"Yes",Applications!$J$2:$J$3144,Analysis!$B$2),0) -> 6.33125 | K31: =H31-ROW()/100000 -> 15.99969

Sheet Assumptions
A1: Assumptions & Lookup Tables
A2: Blue cells are inputs - edit them and every sheet recalculates.
A3: Readiness Score Weight | B3: Weight | D3: Min Score | E3: Readiness Tier | G3: CTC Band | H3: From (LPA) | I3: To (LPA) | K3: Hiring Stage (in order) | M3: Season Month | N3: Month No. | P3: Batch Selector List
A4: DSA problems solved | B4: 0.3 | D4: 0 | E4: Foundation | G4: Below 5 LPA | H4: 0 | I4: 5 | K4: Applied | M4: Jul | N4: 7 | P4: All
A5: CGPA | B5: 0.2 | D5: 50 | E5: Developing | G5: 5 - 8 LPA | H5: 5 | I5: 8 | K5: Online Test | M5: Aug | N5: 8 | P5: Batch 2024
A6: Projects | B6: 0.2 | D6: 65 | E6: Job-Ready | G6: 8 - 12 LPA | H6: 8 | I6: 12 | K6: Technical Interview | M6: Sep | N6: 9 | P6: Batch 2025
A7: Mock interview score | B7: 0.2 | D7: 80 | E7: Elite | G7: 12 - 18 LPA | H7: 12 | I7: 18 | K7: HR Interview | M7: Oct | N7: 10 | P7: Batch 2026
A8: Internship experience | B8: 0.1 | G8: 18+ LPA | H8: 18 | I8: 999 | K8: Offered | M8: Nov | N8: 11
A9: Total (must be 100%) | B9: =SUM(B4:B8) -> 1 | C9: =IF(ROUND(B9,4)=1,"OK","Weights must sum to 100%") -> OK | M9: Dec | N9: 12
A10: Full-score Target | B10: Value | M10: Jan | N10: 1
A11: DSA problems for a full score | B11: 500 | M11: Feb | N11: 2
A12: Projects for a full score | B12: 5 | M12: Mar | N12: 3
M13: Apr | N13: 4
M14: May | N14: 5
M15: Jun | N15: 6
